---
title: "2023.11.17 til"
excerpt: "오늘 배운 모든 내용"
categories:
  - til
tags:
  - javascript
last_modified_at: 2023-11-17
toc: true
---

# promise

## catch

then 메서드의 두 번째 콜백으로 이전 promise가 rejected 상태가 되었을 때를 핸들링 했다. 사실 더 편한 방법이 있다. 바로 catch 메서드를 사용하는 것.

```javascript
fetch("https://jsonplaceholder.typicode.commmmmm/users")
  .then((response) => response.text())
  .catch((error) => {
    console.log(error);
  })
  .then((result) => {
    console.log(result);
  });
```

위의 코드는 잘못된 url을 입력해 fetch 함수가 반환하는 promise의 상태를 rejected로 만들었다. 그러면 첫 번째 then은 실행되지 않고 바로 두 번째 catch로 간다.  
사실 catch 함수는 then 메서드를 약간 변형한 것으로 볼 수 있다. 위의 코드와 아래 코드는 동일하게 동작한다.

```javascript
fetch("https://jsonplaceholder.typicode.commmmmm/users") // Promise-A
  .then((response) => response.text()) // Promise-B
  .then(undefined, (error) => {
    console.log(error);
  }) // Promise-C
  .then((result) => {
    console.log(result);
  }); // Promise-D
```

이 동작을 다시 뜯어보자. fetch 함수의 작업이 실패해서 `Promise-A` 객체가 rejected 상태가 되면, 첫 번째 then 메소드의 두 번째 콜백이 실행되어야 한다. 하지만 지금 첫 번째 then 메소드에는 두 번째 콜백이 없기 때문에 아무 콜백도 실행되지 않는다. 이 때에는 Promise-B 객체가 Promise-A와 똑같은 rejected 상태가 되고, 동일한 작업 실패 정보를 갖게 된다.  
그럼 이제 rejected 상태가 된 Promise-B에 붙은 then 메소드에는 두 번째 콜백이 있기 때문에 이 두 번째 콜백이 실행된다.  
그리고 마지막 then 함수에서 undefined가 출력이 된다. 왜냐하면 두 번째 then 메서드에서 아무것도 리턴하지 않았기 때문이다. 자바스크립트에서는 아무 값도 리턴하지 않은 경우에 undefined를 리턴한 것으로 간주한다. 그리고 해당 then이 리턴하는 promise 객체는 fulfilled 상태가 되면서, undefined를 작업 성공 결과로 가지게 되는 것이다. 그래서 그 뒤의 then 메소드의 콜백의 파라미터로 undefined가 넘어가서 undefined가 출력된 것.

## catch 메서드 사용법

```javascript
fetch("https://jsonplaceholder.typicode.com/users")
  .then((response) => response.text())
  .catch((error) => {
    console.log(error);
  })
  .then((result) => {
    console.log(result);
    throw new Error("test");
  });
```

위 코드처럼 catch 메서드 뒤에 있는 then 메서드의 콜백에서 에러가 나면 어떻게 될까?  
코드를 실행해보면 받아온 결과를 잘 보여준 후, 그 뒤에서 발생한 에러는 잡지 못하는 것을 알 수 있다.  
마지막 then이 반환하는 promise는 rejected 상대가 되는데, 이렇게 rejected 상태의 promise만 있고, 해결하지 못할 때 브라우저는 에러로 인식한다.  
그렇다면 어떻게 해결할 수 있을까?

```javascript
fetch("https://jsonplaceholder.typicode.com/users")
  .then((response) => response.text())
  .then((result) => {
    console.log(result);
    throw new Error("test");
  })
  .catch((error) => {
    console.log(error);
  });
```

이렇게 catch 메서드를 가장 뒤에 위치시키면 fetch 함수가 실패하든, 그 다음 then 메서드가 실패하든 잡아낼 수 있다.

### catch 메서드 중간에 사용하기

만약 중간에 에러가 발생해도 catch 메소드가 그 대안을 뒤로 넘겨줄 수 있으면 catch 메소드를 중간에 써도 된다.

```javascript
fetch("https://friendbook.com/my/newsfeeds")
  .then((response) => response.json()) // -- A
  .then((result) => {
    // -- B
    const feeds = result;
    // 피드 데이터 가공...
    return processedFeeds;
  })
  .catch((error) => {
    // -- C
    // 미리 저장해둔 일반 뉴스를 보여주기
    const storedGeneralNews = getStoredGeneralNews();
    return storedGeneralNews;
  })
  .then((result) => {
    /* 화면에 표시 */
  }) // -- D
  .catch((error) => {
    /* 에러 로깅 */
  }); // -- E
```

위 코드에서 만약 사용자의 컴퓨터가 인터넷에 연결되어 있지 않은 상태라서 fetch 함수의 작업이 실패한다면 어떻게 될까? fetch 함수의 작업이 실패하면 C 줄의 콜백이 실행된다. C줄의 콜백은 바로 이렇게 저장해둔 일반 뉴스 데이터를 그대로 가져오는 기능을 한다.  
이렇게 Promise Chain 중에서 비록 에러가 발생했다고 해도 만약 실패한 작업 대신 다른 방법을 통해서 작업을 정상적으로 끝마칠 수 있는 상황이라면 catch 메소드를 중간에 사용하기도 한다.

## finally 메서드

만약 promise가 fulfilled 되든 rejected 되든 항상 실행하고 싶은 콜백이 있으면 어떻게 할까?  
그런 콜백을 finally 메서드에 등록하면 된다.

```javascript
fetch("https://jsonplaceholder.typicode.com/users")
  .then((response) => response.text())
  .then((result) => {
    console.log(result);
  })
  .catch((error) => {
    console.log(error);
  })
  .finally(() => {
    console.log("exit");
  });
```

이렇게 finally 메서드는 가장 마지막에 작성한다. finally는 작업 성공 결과나 작업 실패 정보가 필요하지 않기 때문에 콜백에 아무런 파라미터도 전달하지 않는다.

## 직접 만드는 promise

```javascript
const myPromise = new Promise((resolve, reject) => {
  // ...
});
```

이렇게 new 연산자와 생성자 함수로 만들 수 있다.  
여기서 중요한 건, 생성자 함수 내의 함수이다. 이 함수는 executor 함수라고 하며, promise 객체가 생성될 때 자동으로 실행되는 함수이다.  
executor 함수에는 두 개의 파라미터를 받고 있는데, 특별한 동작을 한다. 첫 번째 resolve로 받은 파라미터에는 생성될 promise 객체를 fulfilled 상태로 만들 수 있는 함수가 들어온다. 두 번째 reject로 받은 파라미터에는 생성될 promise 객체를 rejected 상태로 만들 수 있는 함수가 들어온다.  
이게 어떤 의미인지 코드로 살펴보자.

```javascript
const myPromise = new Promise((resolve, reject) => {
  setTimeout(() => {
    resolve("success");
  }, 2000);
});
```

setTimeout 함수로 2초 뒤에 resolve로 받은 콜백 함수를 실행하도록 했다. 즉, myPromise 객체는 2초 후에 fulfilled 상태가 된다는 것이다. 이때, resolve에 넣은 문자열이 myPromise 객체의 작업 성공 결과가 된다. 이제 확인해보자.

```javascript
const myPromise = new Promise((resolve, reject) => {
  setTimeout(() => {
    resolve("success");
  }, 2000);
});

myPromise.then((result) => {
  console.log(result);
});
```

이 코드를 실행시켜보면 약 2초 후 `success`란 문자열이 출력된다. then 메서드 내부의 첫 번째 콜백은 앞선 promise 객체의 상태가 fulfilled 됐을 때 실행되기 때문에, myPromise 객체가 resolve 함수를 통해 fulfilled 상태를 가질 때 실행되며, 그 작업 수행 결과를 result로 받은 것이다.  
이번엔 rejected 상태로 만들어보자.

```javascript
const myPromise = new Promise((resolve, reject) => {
  setTimeout(() => {
    reject(new Error("fail"));
  }, 2000);
});

myPromise.catch((error) => {
  console.log(error);
});
```

이번엔 reject 함수를 사용했다. reject 함수는 생성될 promise 객체의 상태를 rejected로 만든다. 그리고 reject 함수에 아규먼트로 넣은 에러 객체가 작업 실패 정보가 된다.

## Promisify

전통적인 형식의 비동기 실행 함수를 Promise 객체로 감싸서 그 Promise 객체를 리턴하는 형식으로 만드는 작업을 Promisify(프로미스화하다)라고 한다. 예시를 통해 어떻게 작동하는지 알아보자.

```js
function wait(text, milliseconds) {
  setTimeout(() => text, milliseconds);
}
```

위와 같은 wait 함수를 사용해 fetch로 받아온 정보를 2초 뒤에 출력하는 효과를 구현하고 싶다고 해보자. 그래서 아래와 같이 작성했다.

```js
function wait(text, milliseconds) {
  setTimeout(() => text, milliseconds);
}

fetch("https://jsonplaceholder.typicode.com/users")
  .then((response) => response.text())
  .then((result) => wait(`${result} by Codeit`, 2000))
  .then((result) => {
    console.log(result);
  });
```

하지만 실제로 출력되는 건 undefined일 뿐이다. wait 함수는 setTimeout을 실행할 뿐 아무것도 리턴하지 않는다. wait 함수를 실행하는 then 메서드가 리턴하는 promise 객체는 작업 성공 결과로 undefined를 갖는 fulfilled된 promise가 된다.  
이를 해결하기 위해 직접 promise 객체를 생성하면 된다. wait 함수를 바꿔보자.

```js
function wait(text, milliseconds) {
  const p = new Promise((resolve, reject) => {
    setTimeout(() => {
      resolve(text);
    }, milliseconds);
  });
  return p;
}
```

## Promisify를 하면 안 되는 함수들

콜백을 여러 번 실행하는 함수들(setInterval, addEventListener 등)인 경우에는 이렇게 Promisify하면 안 된다. 왜냐하면 Promise 객체는 한번 pending 상태에서 fulfilled 또는 rejected 상태가 되고나면 그 뒤로는 그 상태와 결과가 바뀌지 않기 때문이다. 다음의 예제를 보자.

```javascript
const box = document.getElementById("test");
let count = 0;

function addEventListener_promisified(obj, eventName) {
  const p = new Promise((resolve, reject) => {
    obj.addEventListener(eventName, () => {
      // addEventListener 메소드
      count += 1;
      resolve(count);
    });
  });
  return p;
}

addEventListener_promisified(box, "click").then((eventCount) => {
  console.log(eventCount);
});
```

addEventListener_promisified 함수의 아규먼트로 DOM 객체 box와 문자열 'click'을 넣어서 box 객체가 클릭 이벤트에 반응하도록 했다. 하지만 이 코드를 실행하고 box를 클릭해보면 처음에 1이 딱 출력되고 나서 그 다음 count 값들은 출력되지 않는다.  
왜냐하면 pending 상태에 있던 Promise 객체(여기서는 p 객체)가 한번 fulfilled 상태 또는 rejected 상태가 되고 나면 Promise 객체의 상태 및 결과가 고정되어 그 뒤로는 바뀌지 않기 때문이다. 그래서 then 메소드 안의 콜백도 처음 클릭했을 때 딱 한번 실행되고 끝인 것이다.

## 이미 상태가 결정된 promise 객체

1. fulfilled 상태의 Promise 객체 만들기

```js
const p = Promise.resolve("success");
```

Promise의 resolve라는 메소드를 사용하면 바로 fulfilled 상태의 Promise 객체를 만들 수 있다. 위와 같이 쓰면 fulfilled 상태이면서, 작업 성공 결과로 문자열 'success'를 가진 Promise 객체를 만들 수 있다.

2. rejected 상태의 Promise 객체 만들기

```js
const p = Promise.reject(new Error("fail"));
```

Promise의 reject라는 메소드를 사용하면 바로 rejected 상태의 Promise 객체를 만들 수 있다. 위와 같이 쓰면 rejected 상태이면서, 작업 실패 정보로, fail이라는 메시지를 가진 Error 객체를 가진 Promise 객체를 만들 수 있다.

즉, new 생성자와 executor 함수를 사용하는 것 말고도 resolve 메소드나, reject 메소드를 사용하는 방법도 있다는 것.  
어떤 비동기 작업을 처리할 필요가 있다면, new 생성자와 executor 함수를 사용해서 Promise 객체를 만들어야 하지만, 그렇지 않고 바로 상태가 이미 결정된 Promise 객체를 만들고 싶을 때는 이 resolve 또는 reject 메소드를 사용한다.  
예를 들어 함수 안에서 리턴하는 값이 여러 개인 경우 모든 리턴값을 Promise 객체로 통일하고 싶을 때 사용할 수 있는데,

```js
function doSomething(a, b) {
  // ~~
  if (problem) {
    return Promise.reject(new Error("Failed due to.."));
  } else {
    return fetch("https://~");
  }
}
```

이렇게 모든 리턴을 promise로 만들어 이후 핸들링을 일관되게 처리할 수 있도록 만들 수 있다.

## promise에 대한 오해

Promise 객체가 pending 상태일 때 미리 then 메소드가 붙어있어야만 나중에 이 Promise 객체가 fulfilled 상태 또는 rejected 상태가 되었을 때 그 결과(작업 성공 결과 또는 작업 실패 정보)를 콜백의 파라미터로 받을 수 있고, 이미 fulfilled 상태 또는 rejected 상태가 된 Promise 객체의 경우에는 then 메소드를 붙여도 그 결과를 콜백에서 받지 못한다고 오해하는 경우가 있다.  
하지만 위의 resolve, reject 메소드에서도 봤듯이 이미 fulfilled 또는 rejected 상태가 결정된 Promise 객체라도 then 메소드를 붙이면, 콜백에서 해당 작업 성공 결과 또는 작업 실패 정보를 받아올 수 있다. 시점과는 상관이 없는 개념인 것이다.  
Promise 객체의 상태가 fulfilled 또는 rejected 상태이기만 하면, 어느 시점이든, 몇 번이든 then 메소드를 붙여서 해당 결과를 가져올 수 있다.

## 여러 개의 promise 객체 한꺼번에 다루기

1. all 메서드

```js
// 1번 직원 정보
const p1 = fetch("https://learn.codeit.kr/api/members/1").then((res) =>
  res.json()
);
// 2번 직원 정보
const p2 = fetch("https://learn.codeit.kr/api/members/2").then((res) =>
  res.json()
);
// 3번 직원 정보
const p3 = fetch("https://learn.codeit.kr/api/members/3").then((res) =>
  res.json()
);

Promise.all([p1, p2, p3]).then((results) => {
  console.log(results); // Array : [1번 직원 정보, 2번 직원 정보, 3번 직원 정보]
});
```

all 메소드는 무슨 기능을 하는 걸까? all 메소드도 then 메소드처럼 새로운 Promise 객체를 리턴하는데, 이렇게 아규먼트로 들어온 배열 안에 있는 모든 Promise 객체가 pending 상태에서 fulfilled 상태가 될 때까지 기다린다. 아규먼트의 모든 Promise 객체들이 fulfilled 상태가 되면, all 메소드가 리턴했던 Promise 객체는 fulfilled 상태가 되고, 각 Promise 객체의 작업 성공 결과들로 이루어진 배열을 그 작업 성공 결과로 갖게 된다.  
즉, all 메소드가 리턴한 Promise 객체는, 각 개별 Promise 객체의 작업 성공 결과로 이루어진 배열을 자신의 작업 성공 결과로 갖는다는 것을 알 수 있다.

그런데 만약 아규먼트로 받은 promise 객체중 하나라도 rejected 상태가 되면 어떻게 될까?  
all 메소드가 리턴한 Promise 객체는 실패한 작업의 promise 객체처럼 rejected 상태가 되고 동일한 작업 실패 정보를 갖게 된다. 이렇게 all 메소드는 하나의 Promise 객체라도 rejected 상태가 되면, 전체 작업이 실패한 것으로 간주해야 할 때 사용한다.

2. race 메소드

race 메소드도 all 메소드와 마찬가지로 여러 Promise 객체들이 있는 배열을 아규먼트로 받는다. 그리고 race 메소드도 all 메소드처럼 Promise 객체를 리턴한다.  
하지만 race 메소드가 리턴한 Promise 객체는 아규먼트로 들어온 배열의 여러 Promise 객체들 중에서 가장 먼저 fulfilled 상태 또는 rejected 상태가 된 Promise 객체와 동일한 상태와 결과를 갖게 된다.

3. allSettled 메소드

배열 내의 모든 Promise 객체가 fulfilled 또는 rejected 상태가 되기까지 기다리고, pending 상태의 Promise 객체가 하나도 없게 되면, allSettled 메소드가 리턴한 Promise 객체의 상태값은 fulfilled 상태가 되고 그 작업 성공 결과로, 하나의 배열을 갖게 된다. 이 배열에는 아규먼트로 받았던 배열 내의 각 promise 객체의  
(1) 최종 상태를 status 프로퍼티,  
(2) 그 작업 성공 결과는 value 프로퍼티,  
(3) 그 작업 실패 정보는 reason 프로퍼티  
에 담은 객체들이 요소로 존재한다.
아래가 그 예시이다.

```js
[
   {status: "fulfilled", value: 1},
   {status: "fulfilled", value: 2},
   {status: "fulfilled", value: 3},
   {status: "rejected",  reason: Error: an error}
]
```

참고로 fulfilled 상태와 rejected 상태를 묶어서 settled 상태라고 하는데, allSettled 메소드는 말 그대로 배열 속 Promise 객체들이 settled 상태가 되기만 하면 되는 것이다. 이에 반해 위에서 배운 all 메소드는 모든 Promise 객체들이 fulfilled 상태가 되기를 기다리는 것이다.

4. any 메소드

여러 Promise 객체들 중에서 가장 먼저 fulfilled 상태가 된 Promise 객체의 상태와 결과가 any 메소드가 리턴한 Promise 객체에도 똑같이 반영된다. 만약 모든 Promise 객체가 rejected 상태가 되어버리면 AggregateError라고 하는 에러를 작업 실패 정보로 갖고 rejected 상태가 된다. any라는 단어의 뜻처럼 배열 속의 Promise 객체 중 단 하나라도 fulfilled 상태가 되면 되는 것이다.
